<?xml version="1.0"?>
<robot name="r2d2">

  <material name="blue">
    <color rgba="0 0 0.8 1"/>
  </material>
  <material name="black">
    <color rgba="0 0 0 1"/>
  </material>
  <material name="white">
    <color rgba="1 1 1 1"/>
  </material>

  <link name="base_link">
    <visual>
      <geometry>
        <cylinder length="0.7" radius="0.27"/>
      </geometry>
      <material name="blue"/>
    </visual>
    <collision>
      <origin xyz="0 0 -0.12"/>
      <geometry>
        <box size="0.60 0.72 0.24"/>
      </geometry>
    </collision>
    <inertial>
      <origin xyz="0 0 -0.12"/>
      <mass value="22.0"/>
      <inertia ixx="1.2" ixy="0.0" ixz="0.0"
               iyy="1.5" iyz="0.0" izz="1.2"/>
    </inertial>
  </link>

  <link name="right_leg">
    <visual>
      <geometry>
        <box size="0.6 0.1 0.2"/>
      </geometry>
      <origin rpy="0 1.57075 0" xyz="0 0 -0.3"/>
      <material name="white"/>
    </visual>
    <collision>
      <geometry>
        <box size="0.6 0.1 0.2"/>
      </geometry>
      <origin rpy="0 1.57075 0" xyz="0 0 -0.3"/>
    </collision>
    <inertial>
      <mass value="1.0"/>
      <inertia ixx="0.02" ixy="0.0" ixz="0.0"
               iyy="0.02" iyz="0.0" izz="0.02"/>
    </inertial>
  </link>

  <joint name="base_to_right_leg" type="fixed">
    <parent link="base_link"/>
    <child link="right_leg"/>
    <origin xyz="0 -0.22 0.25"/>
  </joint>

  <link name="left_leg">
    <visual>
      <geometry>
        <box size="0.6 0.1 0.2"/>
      </geometry>
      <origin rpy="0 1.57075 0" xyz="0 0 -0.3"/>
      <material name="white"/>
    </visual>
    <collision>
      <geometry>
        <box size="0.6 0.1 0.2"/>
      </geometry>
      <origin rpy="0 1.57075 0" xyz="0 0 -0.3"/>
    </collision>
    <inertial>
      <mass value="1.0"/>
      <inertia ixx="0.02" ixy="0.0" ixz="0.0"
               iyy="0.02" iyz="0.0" izz="0.02"/>
    </inertial>
  </link>

  <joint name="base_to_left_leg" type="fixed">
    <parent link="base_link"/>
    <child link="left_leg"/>
    <origin xyz="0 0.22 0.25"/>
  </joint>

  <link name="right_base">
    <visual>
      <geometry>
        <box size="0.4 0.1 0.1"/>
      </geometry>
      <material name="white"/>
    </visual>
    <collision>
      <geometry>
        <box size="0.4 0.1 0.1"/>
      </geometry>
    </collision>
    <inertial>
      <mass value="0.5"/>
      <inertia ixx="0.01" ixy="0.0" ixz="0.0"
               iyy="0.01" iyz="0.0" izz="0.01"/>
    </inertial>
  </link>

  <joint name="right_base_joint" type="fixed">
    <parent link="right_leg"/>
    <child link="right_base"/>
    <origin xyz="0 0 -0.6"/>
  </joint>

  <link name="left_base">
    <visual>
      <geometry>
        <box size="0.4 0.1 0.1"/>
      </geometry>
      <material name="white"/>
    </visual>
    <collision>
      <geometry>
        <box size="0.4 0.1 0.1"/>
      </geometry>
    </collision>
    <inertial>
      <mass value="0.5"/>
      <inertia ixx="0.01" ixy="0.0" ixz="0.0"
               iyy="0.01" iyz="0.0" izz="0.01"/>
    </inertial>
  </link>

  <joint name="left_base_joint" type="fixed">
    <parent link="left_leg"/>
    <child link="left_base"/>
    <origin xyz="0 0 -0.6"/>
  </joint>

  <link name="right_front_wheel">
    <visual>
      <origin rpy="1.57075 0 0" xyz="0 0 0"/>
      <geometry>
        <cylinder radius="0.035" length="0.03"/>
      </geometry>
      <material name="black"/>
    </visual>
    <collision>
      <origin rpy="1.57075 0 0" xyz="0 0 0"/>
      <geometry>
        <cylinder radius="0.035" length="0.03"/>
      </geometry>
    </collision>
    <inertial>
      <mass value="0.2"/>
      <inertia ixx="0.001" ixy="0.0" ixz="0.0"
               iyy="0.001" iyz="0.0" izz="0.001"/>
    </inertial>
  </link>

  <joint name="right_front_wheel_joint" type="continuous">
    <parent link="right_base"/>
    <child link="right_front_wheel"/>
    <origin xyz="0.133333333333 0 -0.07"/>
    <axis xyz="0 1 0"/>
  </joint>

  <link name="right_back_wheel">
    <visual>
      <origin rpy="1.57075 0 0" xyz="0 0 0"/>
      <geometry>
        <cylinder radius="0.035" length="0.03"/>
      </geometry>
      <material name="black"/>
    </visual>
    <collision>
      <origin rpy="1.57075 0 0" xyz="0 0 0"/>
      <geometry>
        <cylinder radius="0.035" length="0.03"/>
      </geometry>
    </collision>
    <inertial>
      <mass value="0.2"/>
      <inertia ixx="0.001" ixy="0.0" ixz="0.0"
               iyy="0.001" iyz="0.0" izz="0.001"/>
    </inertial>
  </link>

  <joint name="right_back_wheel_joint" type="fixed">
    <parent link="right_base"/>
    <child link="right_back_wheel"/>
    <origin xyz="-0.133333333333 0 -0.07"/>
  </joint>

  <link name="left_front_wheel">
    <visual>
      <origin rpy="1.57075 0 0" xyz="0 0 0"/>
      <geometry>
        <cylinder radius="0.035" length="0.03"/>
      </geometry>
      <material name="black"/>
    </visual>
    <collision>
      <origin rpy="1.57075 0 0" xyz="0 0 0"/>
      <geometry>
        <cylinder radius="0.035" length="0.03"/>
      </geometry>
    </collision>
    <inertial>
      <mass value="0.2"/>
      <inertia ixx="0.001" ixy="0.0" ixz="0.0"
               iyy="0.001" iyz="0.0" izz="0.001"/>
    </inertial>
  </link>

  <joint name="left_front_wheel_joint" type="continuous">
    <parent link="left_base"/>
    <child link="left_front_wheel"/>
    <origin xyz="0.133333333333 0 -0.07"/>
    <axis xyz="0 1 0"/>
  </joint>

  <link name="left_back_wheel">
    <visual>
      <origin rpy="1.57075 0 0" xyz="0 0 0"/>
      <geometry>
        <cylinder radius="0.035" length="0.03"/>
      </geometry>
      <material name="black"/>
    </visual>
    <collision>
      <origin rpy="1.57075 0 0" xyz="0 0 0"/>
      <geometry>
        <cylinder radius="0.035" length="0.03"/>
      </geometry>
    </collision>
    <inertial>
      <mass value="0.2"/>
      <inertia ixx="0.001" ixy="0.0" ixz="0.0"
               iyy="0.001" iyz="0.0" izz="0.001"/>
    </inertial>
  </link>

  <joint name="left_back_wheel_joint" type="fixed">
    <parent link="left_base"/>
    <child link="left_back_wheel"/>
    <origin xyz="-0.133333333333 0 -0.07"/>
  </joint>

  <link name="stability_skid">
    <collision>
      <origin xyz="0 0 0"/>
      <geometry>
        <box size="0.58 0.68 0.08"/>
      </geometry>
    </collision>
    <inertial>
      <mass value="0.01"/>
      <inertia ixx="0.0001" ixy="0.0" ixz="0.0"
               iyy="0.0001" iyz="0.0" izz="0.0001"/>
    </inertial>
  </link>

  <joint name="base_to_stability_skid" type="fixed">
    <parent link="base_link"/>
    <child link="stability_skid"/>
    <origin xyz="0 0 -0.34"/>
  </joint>

  <link name="head">
    <visual>
      <geometry>
        <sphere radius="0.27"/>
      </geometry>
      <material name="white"/>
    </visual>
    <collision>
      <geometry>
        <sphere radius="0.27"/>
      </geometry>
    </collision>
    <inertial>
      <mass value="0.35"/>
      <inertia ixx="0.02" ixy="0.0" ixz="0.0"
               iyy="0.02" iyz="0.0" izz="0.02"/>
    </inertial>
  </link>

  <joint name="head_swivel" type="revolute">
    <parent link="base_link"/>
    <child link="head"/>
    <axis xyz="0 0 1"/>
    <origin xyz="0 0 0.35"/>
    <limit lower="-3.14159" upper="3.14159" effort="5.0" velocity="1.5"/>
    <dynamics damping="2.0" friction="1.0"/>
  </joint>

  <link name="box">
    <visual>
      <geometry>
        <box size="0.08 0.2 0.1"/>
      </geometry>
      <material name="white"/>
    </visual>
    <collision>
      <geometry>
        <box size="0.08 0.2 0.1"/>
      </geometry>
    </collision>
    <inertial>
      <mass value="0.05"/>
      <inertia ixx="0.001" ixy="0.0" ixz="0.0"
               iyy="0.001" iyz="0.0" izz="0.001"/>
    </inertial>
  </link>

  <joint name="box_joint" type="fixed">
    <parent link="head"/>
    <child link="box"/>
    <origin xyz="0.16 0 0.16"/>
  </joint>

  <link name="camera_link">
    <visual>
      <geometry>
        <box size="0.05 0.08 0.05"/>
      </geometry>
      <material name="black"/>
    </visual>
    <collision>
      <geometry>
        <box size="0.05 0.08 0.05"/>
      </geometry>
    </collision>
    <inertial>
      <mass value="0.01"/>
      <inertia ixx="0.0001" ixy="0.0" ixz="0.0"
               iyy="0.0001" iyz="0.0" izz="0.0001"/>
    </inertial>
  </link>

  <joint name="box_to_camera" type="fixed">
    <parent link="box"/>
    <child link="camera_link"/>
    <origin xyz="0 0 0.08"/>
  </joint>

  <link name="laser_link">
    <visual>
      <geometry>
        <cylinder radius="0.03" length="0.05"/>
      </geometry>
      <material name="black"/>
    </visual>
    <collision>
      <geometry>
        <cylinder radius="0.03" length="0.05"/>
      </geometry>
    </collision>
    <inertial>
      <mass value="0.01"/>
      <inertia ixx="0.0001" ixy="0.0" ixz="0.0"
               iyy="0.0001" iyz="0.0" izz="0.0001"/>
    </inertial>
  </link>

  <joint name="box_to_laser" type="fixed">
    <parent link="box"/>
    <child link="laser_link"/>
    <origin xyz="0.08 0 0.02"/>
  </joint>

  <gazebo>
    <plugin name="differential_drive_controller"
            filename="libgazebo_ros_diff_drive.so">
      <leftJoint>left_front_wheel_joint</leftJoint>
      <rightJoint>right_front_wheel_joint</rightJoint>
      <wheelSeparation>0.60</wheelSeparation>
      <wheelDiameter>0.07</wheelDiameter>
      <commandTopic>cmd_vel</commandTopic>
      <odometryTopic>odom</odometryTopic>
      <odometryFrame>odom</odometryFrame>
      <robotBaseFrame>base_link</robotBaseFrame>
      <publishWheelTF>false</publishWheelTF>
      <publishOdomTF>true</publishOdomTF>
      <publishWheelJointState>true</publishWheelJointState>
      <wheelAcceleration>0</wheelAcceleration>
      <wheelTorque>5</wheelTorque>
      <updateRate>100</updateRate>
    </plugin>
  </gazebo>
<gazebo reference="base_link">
  <material>Gazebo/Blue</material>
</gazebo>

<gazebo reference="right_leg">
  <material>Gazebo/White</material>
</gazebo>

<gazebo reference="left_leg">
  <material>Gazebo/White</material>
</gazebo>

<gazebo reference="right_base">
  <material>Gazebo/White</material>
</gazebo>

<gazebo reference="left_base">
  <material>Gazebo/White</material>
</gazebo>

<gazebo reference="right_front_wheel">
  <material>Gazebo/Black</material>
</gazebo>

<gazebo reference="left_front_wheel">
  <material>Gazebo/Black</material>
</gazebo>

<gazebo reference="right_back_wheel">
  <material>Gazebo/Black</material>
</gazebo>

<gazebo reference="left_back_wheel">
  <material>Gazebo/Black</material>
</gazebo>

<gazebo reference="head">
  <material>Gazebo/White</material>
</gazebo>

<gazebo reference="box">
  <material>Gazebo/Blue</material>
</gazebo>

</robot>
